Workbook

Sheet Portafolio P&D
A2: N° | B2: Código de Planeamiento | C2: Nombre del Proyecto | D2: Alcance del Proyecto | E2: Gerencia Líder | F2: Líder del Proyecto | G2: Usuario Funcional | H2: Gestor de Planeamiento | I2: Presupuesto asignado | J2: Valor Ganado (EV) | K2: Costo Actual (AC) | L2: CPI | M2: Fecha Comité Ejec. Proy. | N2: N° Acta Comité (aprobación) | O2: Dimensión | P2: Objetivo | Q2: Año Inicio Planificado | R2: Año Fin Planificado | S2: N° Solicitudes de cambio | T2: Componente Tecnológico | U2: Transformación Digital | V2: Cartera | W2: Anexo 1 (Modelo de Negocio) | X2: Líder Técnico | Y2: Fecha Inicio | Z2: Fecha Fin | AA2: % Avance Planificado | AB2: % Avance ejecutado | AC2: Desv. % | AD2: Estado | AE2: SEGUIMIENTO (Planeamiento y Control de Gestión)
A3: 1 | B3: Iniciativa | C3: Nuevo Pagalo.pe | D3: Implementar una nueva web que cumpla con características clave, como la simplicidad, la intuitividad y la modernidad. Permitirá a los clientes y ciudadanos realizar de forma rápida y eficiente sus Operaciones de pago de tasas de manera virtual. | E3: Banca Digital | F3: Lenin Valencia | G3: - | H3: No definido | I3: 1500000 | J3: =Tabla3[[#This Row],[Presupuesto asignado]]/2 -> 750000 | K3: =Tabla3[[#This Row],[Valor Ganado (EV)]] -> 750000 | L3: =Tabla3[[#This Row],[Valor Ganado (EV)]]/Tabla3[[#This Row],[Costo Actual (AC)]] -> 1 | M3: 45121 | N3: No indica | O3: Servicio a los Clientes | P3: De cara al ciudadano | Q3: 2023 | R3: 2025 | S3: 1 | T3: Si | U3: No | V3: Nuevo Págalo | W3: No | X3: Lupe Mayo | Y3: 45139 | Z3: 45852 | AA3: 0 | AB3: 0 | AC3: =Tabla3[[#This Row],[% Avance ejecutado]]-Tabla3[[#This Row],[% Avance Planificado]]/Tabla3[[#This Row],[% Avance Planificado]] -> #DIV/0! | AD3: 04. Cerrado | AE3: 23/05/24 Mediante acta de comité estratégico de proyectos de fecha 06.05.24 se informa que se acordo que el proyecto pasa a estado de "Cerrado", por lo cual deben presentar acta de cierre y lecciones aprendidas. 03/05/2024 Proyecto se encuentra a la espera del Anexo 1 08/04/24 Se realizó cambio de fecha de fin de proyecto de 2024 a 2025 22/03/24 Pendiente que el usuario remita modelo de negocio para registrar el Proyecto en la demanda estrategica priorizada. Modelo de Negocio Observado
A4: 2 | B4: Iniciativa | C4: Nuevo Plataforma App Mobile BN | D4: Implementar una nueva plataforma APP Mobile con funcionalidades adicionales (QR, Pagos) e Integrar más servicios varios a pagar, para ampliar el uso del dinero por canales digitales. A fin de brindar a los usuarios una aplicación y plataforma virtual que les permita migrar sus Operaciones presenciales hacia entornos digitales. | E4: Banca Digital | F4: Lenin Valencia | G4: - | H4: No definido | I4: 2500000 | J4: =Tabla3[[#This Row],[Presupuesto asignado]]/2 -> 1250000 | K4: =Tabla3[[#This Row],[Valor Ganado (EV)]] -> 1250000 | L4: =Tabla3[[#This Row],[Valor Ganado (EV)]]/Tabla3[[#This Row],[Costo Actual (AC)]] -> 1 | M4: 45121 | N4: No indica | O4: Servicio a los Clientes | P4: De cara al ciudadano | Q4: 2023 | R4: 2025 | T4: Si | U4: No | V4: Nuevo APP | W4: No | X4: Alex Valencia | Y4: 44972 | Z4: 45691 | AA4: 0 | AB4: 0 | AC4: =Tabla3[[#This Row],[% Avance ejecutado]]-Tabla3[[#This Row],[% Avance Planificado]]/Tabla3[[#This Row],[% Avance Planificado]] -> #DIV/0! | AD4: 04. Cerrado | AE4: 23/05/24 Mediante acta de comité estratégico de proyectos con fecha 06.05.24 se informa que se aprobo el control de cambios del proyecto y se unificara con Hombe Banking "Multired Virtual", se debe presentar nuevo cronograma- Unifcado. 16/05/2024 Mediante correo de Judit Nino se solicita la revisión de TDRs para su posterior recolección de firmas 15/05/2024 Por correo de Roger Guzman se menciona que se ha completado la abosluciòn de consultas de los participantes el proceso de contrataciòn.Entrega TDR y Excel de consultas. 03/05/2024 En absolución de consultas del proceso Logístico 24/04/2024 Mediante correo remitido por Jorge Guzman se indica los resultados de la reunión del día 19.04 puesto que existen consultas técnicas en el proceso de contratación en la fusión del proyecto y estas deben ser centralizadas y distribuidas por la Oficina de Proyectos y Procesos de TIC. 08/04/24 Se cambia las fechas de inicio y Fin por medidas de control de cambios y unificación de proyecto con "Nueva Homebanking Multired Virtual" 22/03/24 Isabel informa que los Proyectos del Nuevo APP y MV se van a fusionar como un solo proyecto, no será atendido por Fábrica sino se contratará un proveedor. Se observa los entregables asociados a API que se encuentran al 100%, se debe validar si son solo definiciones o implementaciones para sincerar el 41% de avance. Isabel coordinará con Bca DIgital la gestión de cambio de ser necesario. Se debe actualizar además la fecha de inicio y fin en caso corresponda. Isabel agendará una reunión previa con usuario, planemiento y TI. Pendiente que el usuario remita modelo de negocio para registrar el Proyecto en la demanda estrategica priorizada.
A5: 3 | B5: Iniciativa | C5: Nuevo Home Banking "Multired Virtual" | D5: Rediseño e implementación de una Nueva Plataforma con funcionalidades adicionales (Pagos e integrar más servicios varios a pagar), ampliar el uso del dinero por canales digitales. A fin de brindar a los usuarios peruanos una aplicación y plataforma virtual que les permita migrar sus Operaciones presenciales hacia entornos digitales. | E5: Banca Digital | F5: Lenin Valencia | G5: - | H5: No definido | I5: 2500000 | J5: =Tabla3[[#This Row],[Presupuesto asignado]]/2 -> 1250000 | K5: =Tabla3[[#This Row],[Valor Ganado (EV)]] -> 1250000 | L5: =Tabla3[[#This Row],[Valor Ganado (EV)]]/Tabla3[[#This Row],[Costo Actual (AC)]] -> 1 | M5: 45121 | N5: No indica | O5: Servicio a los Clientes | P5: De cara al ciudadano | Q5: 2023 | R5: 2025 | T5: Si | U5: No | V5: Nuevo HB | W5: No | X5: Alex Valencia | Y5: 44972 | Z5: 45691 | AA5: 0 | AB5: 0 | AC5: =Tabla3[[#This Row],[% Avance ejecutado]]-Tabla3[[#This Row],[% Avance Planificado]]/Tabla3[[#This Row],[% Avance Planificado]] -> #DIV/0! | AD5: 04. Cerrado | AE5: 23/05/24 Mediante acta de comité estratégico de proyectos con fecha 06.05.24 se informa que se aprobo el control de cambios del proyecto y se unificara con Hombe Banking "Multired Virtual", se debe presentar nuevo cronograma- Unifcado. 16/05/2024 Mediante correo de Judit Nino se solicita la revisión de TDRs para su posterior recolección de firmas 15/05/2024 Por correo de Roger Guzman se menciona que se ha completado la abosluciòn de consultas de los participantes el proceso de contrataciòn.Entrega TDR y Excel de consultas. 03/05/2024 En absolución de consultas del proceso Logístico 24/04/2024 Mediante correo remitido por Jorge Guzman se indica los resultados de la reunión del día 19.04 puesto que existen consultas técnicas en el proceso de contratación en la fusión del proyecto y estas deben ser centralizadas y distribuidas por la Oficina de Proyectos y Procesos de TIC. 08/04/024 Existe un control de cambios y un plan de unificación con el proyecto "Nuevo APP BN" 22/03/24 Idem Nuevo APP BN
A6: 4 | B6: Iniciativa | C6: Nuevo Agente Corresponsal / Pago de Tasas | D6: Implementación de una nueva plataforma móvil para la administración y gestión de la Red de Agentes Corresponsales. Permite realizar Operaciones como depósitos, retiros y pagos de tasas a través de dispositivos móviles, brindando mayor independencia y control al Banco en la atención y configuración de los agentes. Mejora la eficiencia y calidad del servicio, ofreciendo una experiencia más conveniente para los clientes. | E6: Banca Digital | F6: Lenin Valencia | G6: Alexis Junchaya | H6: No definido | I6: 550000 | J6: =Tabla3[[#This Row],[Presupuesto asignado]]/2 -> 275000 | K6: =Tabla3[[#This Row],[Valor Ganado (EV)]] -> 275000 | L6: =Tabla3[[#This Row],[Valor Ganado (EV)]]/Tabla3[[#This Row],[Costo Actual (AC)]] -> 1 | M6: 45121 | N6: No indica | O6: Servicio a los Clientes | P6: De cara al ciudadano | Q6: 2023 | R6: 2025 | T6: Si | U6: No | V6: Nuevo Agente | W6: No | X6: Juan Ortega | Y6: 45127 | Z6: 45821 | AA6: 0 | AB6: 0 | AC6: =Tabla3[[#This Row],[% Avance ejecutado]]-Tabla3[[#This Row],[% Avance Planificado]]/Tabla3[[#This Row],[% Avance Planificado]] -> #DIV/0! | AD6: 04. Cerrado | AE6: 23/05/24 Mediante acta de comité estratégico de proyectos con fecha 06.05.24 se informa que se acordo que el proyecto pasa a estado de "Cerrado" , por lo cual deben presentar acta de cierre y lecciones aprendidas. 03/05/2024 A la espera de del Anexo 1 Modelo de Negocio 08/04/24 Se cambia la fecha de Fin de proyecto de 2024 a 2025 20/3/2024 Usuario se encuentran avanzando con su primer entregable que son las TDRs. Pendiente que el usuario remita modelo de negocio para registrar el Proyecto en la demanda estrategica priorizada. Modelo de Negocio Observado
A7: 5 | B7: PROKDD-EO05-23-4 | C7: Pruebas de Concepto - Quiosko digital dispensador de tarjetas | D7: La implementacion de los quioscos digitales brindará terminales de autoservicio para que los clientes puedan interactuar con informacion y contenido digital con el fin de facilitar y acelerar sus solicitudes y requerimientos, los cuales actualmente se hacen de forma presencial. | E7: Banca Digital | F7: Marita Carbajo | G7: Por definir | H7: Noe Figueroa | I7: S/ 1.659,450 | J7: =Tabla3[[#This Row],[Presupuesto asignado]]/2 -> #VALUE! | K7: =Tabla3[[#This Row],[Valor Ganado (EV)]] -> #VALUE! | L7: =Tabla3[[#This Row],[Valor Ganado (EV)]]/Tabla3[[#This Row],[Costo Actual (AC)]] -> #VALUE! | M7: 45121 | N7: Acta Nº8-2023 | O7: Servicio a los Clientes | P7: De cara al ciudadano | Q7: 2023 | R7: 2026 | S7: 5 | T7: Si | U7: Sí | V7: Quiosco Multimedia | W7: Si | X7: Jorge Campos | Y7: 45110 | Z7: 46081 | AA7: 0.88 | AB7: 0.85 | AC7: =Tabla3[[#This Row],[% Avance ejecutado]]-Tabla3[[#This Row],[% Avance Planificado]]/Tabla3[[#This Row],[% Avance Planificado]] -> -0.15 | AD7: 02. En Curso | AE7: 14/04/2026: En el mes de marzo, al cierre se vienen realizando pruebas funcionales y técnicas en ambiente de desarrollo; sin embargo, las pruebas funcionales presentaron retrasos por inestabilidad del ambiente y demoras en levantar observaciones por parte de TI. 23/03/2026: Al cierre del mes de febrero de 2026 se vienen realizando pruebas funcionales y técnicas en ambiente de desarrollo. 20/03/2026: Según el acta de reunión del comité de proyectos del mes de enero, el proyecto presentó un ligero retraso al cierre de diciembre 2025, no completándose las pruebas en ambiente de BN Banco. El proveedor ha solicitado 3 ampliaciones a la fecha y mantiene un atraso de un mes en las pruebas de desarrollo, lo cual impactará en el cronograma planificado actual. 25/02/2026: Al cierre de enero de 2026 se registró un retraso atribuible al proveedor que impidió completar la implementación del ambiente de desarrollo para las pruebas de BN Banco. El proveedor solicitó tres ampliaciones de plazo (12, 28 y 13 días), aprobándose 12, 18 y 8 días, respectivamente; sin embargo, mantiene un retraso aproximado de un mes, lo que afecta el cronograma del proyecto, por lo que se viene preparando un control de cambios para sincerar los plazos. 21/01/2026: Se han concluido la configuración y desarrollo de la aplicación en el equipo, dando lugar a las coordinaciones e inicio de las pruebas en ambiente de desarrollo. 30/11/2025: Se han concluido la revisión de las APIS desarrolladas para la integración del quiosco con el CORE Banco; se están haciendo las coordinaciones para el inicio de las pruebas en ambiente de desarrollo (preparación ambiente). 31/10/2025: Según la información enviada de Planeamiento en el mes de Octubre se precisa lo siguiente: "Al cierre de octubre, el Quiosco Multimedia trasladado al laboratorio del Banco se encuentra en proceso de instalación, configuración y desarrollo de la aplicación, en coordinación con las áreas técnicas y funcionales. Se registraron retrasos en actividades del Hito 3 relacionadas con la integración y pruebas del sistema; sin embargo, se prevé su recuperación mediante la ejecución en paralelo de los entregables “Configuración de Bienes y Pase a Producción” y “Desarrollo y Puesta en Producción de Transacciones”. Se envió 01 quioscos adicional en el laboratorio. En ese contexto, se viene solicitando un control de cambio para sincerar los plazos y optimizar la gestión del cronograma, asegurando la continuidad y calidad del proyecto." 30/09/2025: Según la información enviada de Planeamiento en el mes de Septiembre se precisa lo siguiente: Al cierre de Septiembre, el Quiosco Multimedia trasladado al laboratorio del Banco se encuentra en proceso de instalación, configuración y desarrollo de la aplicación, en coordinación con las áreas técnicas y funcionales. Se registraron retrasos en actividades del Hito 3 relacionadas con la integración y pruebas del sistema. Sin embargo, se prevé su recuperación mediante la ejecución en paralelo de los entregables “Configuración de Bienes y Pase a Producción” y “Desarrollo y Puesta en Producción de Transacciones”. En ese contexto, se viene solicitando un control de cambio para sincerar los plazos y optimizar la gestión del cronograma, asegurando la continuidad y calidad del proyecto. 16/09/2025: Según la información enviada de Planeamiento en el mes de Agosto se precisa lo siguiente: Al cierre de agosto, el Quiosco multimedia trasladado al laboratorio del Banco (Sede principal), se encuentra en proceso de instalación, configuración y desarrollo de la aplicación por parte del contratista (hardware y software), en coordinación con las áreas técnica y funcional. Si bien se han registrado retrasos en las actividades: Instalación de Quioscos en laboratorio, Construcción Transacción Reposición y actualización de datos, Pruebas en ambiente de desarrollo, Acta de Conformidad en Desarrollo y Pruebas en ambiente de certificación del proyecto, se prevé su recuperación mediante la ejecución en paralelo de las primeras dos actividades de los siguientes entregables planificados. · Entregable: Configuración de Bienes y Pase a Producción · Entregable: Desarrollo y puesta en producción de transacciones La ejecución simultánea de estas actividades permitirá optimizar los tiempos, reducir el impacto de los retrasos registrados y asegurar la continuidad del cronograma. 18/08/25: Según la información enviada de Planeamiento en el mes de Julio se precisa lo siguiente: Al cierre del mes de julio, se culminó la verificación de los bienes.(03 quioscos multimedia) que se encuentran internados en el almacén del Banco. 18/07/25: Al 30.06.25, se vienen realizando actividades relacionadas a la verificación de los bienes que se encuentran internados en el almacén del Banco. Se estima concluir con la verificación en el mes de agosto de acuerdo a lo planificado. Asimismo, se concluyó el modelo funcional, lo que corresponde a la actividad interna paralela que se efectúa en coordinación con el proveedor fabricante de los Quioscos. 07/07/2025: Los Informes de Conformidad de equipos se encuentran en proceso de emision para ser reportados a Banca Digital. 11/06/2025:Según la información enviada de Planeamiento en el mes de Mayo se precisa lo siguiente: Las áreas de Sección Soporte de la Infraestructura Tecnológica y Atención a Usuario, Sección Sistemas Bancarios, Sección Canales Presenciales y Subgerencia de Innovación digital ya verificaron los equipos de quioscos multimedia ingresados al almacén del Banco y está en proceso la firma de las actas de conformidad respectivas de cada área. Se espera tener el flujo funcional cerrado, para ello se esta realizando las reuniones de entendimiento entre las áreas responsables. 03/06/2025: Según la información enviada de Planeamiento mediante correo respecto al proyecto en el mes de abril se tiene que: Se recepcionó los quioscos multimedia en el almacén del Banco y se inició las coordinaciones para proceder a la verificación de los equipos durante el mes de mayo. Cabe resaltar que el proveedor efectuó la referida entrega con antelación, dado que estuvo planificada para el mes de julio. 07/05/2025: Según la información enviada por Planeamiento mediante correo: Se encuentra en proceso la definición del esquema de integración de los quioscos con el core del Banco para la transacción de reposición de tarjeta, lo que permitirá continuar con las actividades que se tenían planificadas, 31/12/2024: Se completó la firma del contrato con la empresa ganadora y se tiene un cronograma con control de cambios aprobado por el Comité de proyectos 23/05/24 Mediante comité estratégico del proyecto con fecha 06.05.24 se informa que se aprobó el control de cambios, que implica un nuevo cronograma; el alcance se mantiene. 15/05/2024 Mediante correo de Marita Carbajo entrega ETMS actualizados y deja constancia que con memo N°568-2024-BN-2662 hay consultas de Belltech de ser necesarias agregarlas a ETMS. 02/05/2024 Mediante correo de Hector Sevalla se da a conocer los temas e implementaciones que puede tener el proyecto, se deja en conocimiento la inclusión a un sistema ESP/LINK, aumento de funcionalidades de ATM e inclusión de BEVERTEC. A la espera de agendarse reunión para 02.05 y consolidar los temas pendientes. 26/04/2024 Mediante correo se espera la actualización del documento Anexo 1 que debe ser remitido por el área correspondiente por tener observaciones en el nombre del proyecto y falta de fecha del proyecto. Asi mismo, se espera la solicitud de validación del cronograma del proyecto. Mediante correo se pide reagendar reunión y confirmar la asistencia a esta del Subgerente de Construcción de aplicaciones. 25/04/2024 Mediante correo de Marita Carbajo se da conocimiento de la consulta en coordinacion de Construcción de aplicaciones y el proveedor sobre el intercambio de llaves para que el Kiosko se comporte como un ATM. Se pide agendar reunión para el 26.04 con miembros de TI 24/04/2024 Se entrega vía correo por parte de Marita Carbajo el Anexo 1"Modelo de Negocio". 24/04/2024 Se recibe el correo envíado por Marita Carbajo en el que se notifica la entrega de documentación de Viabilidad Técnica, Modelo funcional y Cronograma del proyecto. Se pide enviar el Modelo de Negocio - Anexo 1 08/04/24 Se realizó cambio de fecha de fin de proyecto de 2023 a 2025 20/03/24 Usuario se encuentra resolviendo las observaciones de las ETMs en coordinación con Logística. Habra un control de cambios, en base al cronograma que presentará el usuario. Pendiente que el usuario remita modelo de negocio para registrar el Proyecto en la demanda estrategica priorizada. Modelo de Negocio Observado
A8: 6 | B8: PRONCR-EO05-23-5 | C8: Pruebas de concepto Cajeros Automáticos Depositarios | D8: La implementacion de los cajeros automaticos para deposito y retiro como prueba de concepto, busca brindar a los clientes una alternativa para que puedan realizar retiros y depositos en horarios distintos al de las agencias logrando de esta manera promover una cultura de autoservicio y una gestion eficeinte del canal | E8: Banca Digital | F8: Diego Marcelo | G8: Por definir | H8: Juan Carlos Palomino | I8: 866957 | J8: 500000 | K8: 800000 | L8: =Tabla3[[#This Row],[Valor Ganado (EV)]]/Tabla3[[#This Row],[Costo Actual (AC)]] -> 0.625 | M8: 45121 | N8: Acta Nº8-2023 | O8: Servicio a los Clientes | P8: De cara al ciudadano | Q8: 2023 | R8: 2026 | S8: 4 | T8: Si | U8: Sí | V8: Cajeros Depositarios | W8: Si | X8: Felix Ochoa | Y8: 45071 | Z8: 46295 | AA8: 0.87 | AB8: 0.84 | AC8: =Tabla3[[#This Row],[% Avance ejecutado]]-Tabla3[[#This Row],[% Avance Planificado]]/Tabla3[[#This Row],[% Avance Planificado]] -> -0.16 | AD8: 02. En Curso | AE8: 14/04/2026: En el mes de marzo, actualmente nos encontramos en la fase de desarrollo e integración de las soluciones: Transacción de Depósito en efectivo sin tarjeta, procesos Batch FISA, DAPH y Contabilización de ATM, así como alertas de Card Reader y RMV4 en consola Truesight; no se han evidenciado retrasos en los desarrollos asociados y, en conjunto con el área de Planeamiento, se realizan seguimientos semanales del proyecto. 23/03/2026: Al cierre de febrero, se está avanzando en la implementación de los flujos principales de depósito (sin tarjeta y contactless), validando las pantallas en front-end para asegurar la mensajería y experiencia de usuario, y definiendo los flujos batch en el backend. 20/03/2026: Según el acta de reunión del comité de proyectos del mes de enero, el proyecto marchó de acuerdo a lo planificado al cierre de diciembre 2025. A la fecha, la Gerencia de Banca Digital ya cuenta con un cronograma detallado del entregable "Configuración de bienes", el cual está siendo firmado por todos los participantes. 21/01/2026: Se identificaron componentes compartidos con Esplink que impactan al proyecto Card Dispenser, por lo que se acordó la coexistencia de cambios en el ambiente de desarrollo y la ejecución de validaciones en ventanas programadas. Se confirmó el despliegue de la integración con el Backend del banco para el viernes 02/01/2026 para iniciar las validaciones de la primera transacción de depósito con tarjeta el lunes 05/01/2026. 30/11/2025: "En el marco del Proyecto Cajeros Depositarios, se realizó el sinceramiento de la ponderación de los avances del proyecto por hito, lo cual fue revisado y discutido en la Reunión del 5 de diciembre, y reflejado en la Ficha de Seguimiento Parte A y Parte B (CC). No obstante, dicho ajuste no fue aprobado en el presente periodo, debido a que corresponde ser gestionado a través del proceso formal de Control de Cambios. Durante la revisión, se identificó que la actualización del porcentaje en la sección Configuración de Bienes al 55% generó un ajuste automático del avance planificado a 35%, manteniéndose alineado con el avance ejecutado, considerando que la fase de Implementación concentra mayor esfuerzo y complejidad. Actualmente, las actividades de configuración de los equipos del proyecto se ejecutan conforme al cronograma aprobado, dentro de los plazos establecidos y sin desviaciones relevantes. El Control de Cambios correspondiente será presentado para su evaluación en el mes de enero de 2026, conforme a lo acordado." 31/10/2025: Según la información enviada de Planeamiento en el mes de Octubre se precisa lo siguiente: Actualmente nos encontramos en la fase de implementación de las configuraciones del Software en el Cajero automático depositario, así mismo, venimos gestionando en conjunto con la empresa Bevertec el inicio de la implementación de la solución en la plataforma Esplink la cual se encuentra en la fase de revisión y aprobación del PCR. 30/09/2025: Según la información enviada de Planeamiento en el mes de Septiembre se precisa lo siguiente: Durante este mes se realizó la verificación física de los equipos, de los cuales en la primera revisión se encontraron observaciones las cuales fueron subsanadas por el proveedor Diebold generando una segunda fase de validación la cual fue conforme. 16/09/2025:Según la información enviada de Planeamiento en el mes de Agosto se precisa lo siguiente: Se efectuó la entrega de los cinco (05) cajeros depositarios conforme a lo programado. Actualmente, el proyecto se encuentra en la fase de verificación física de los equipos, previa a su puesta en funcionamiento. 18/08/25: Según la información enviada de Planeamiento en el mes de Julio se precisa lo siguiente: Monitoreo de entrega de equipos: Al terminar julio, siguen vigilando que los equipos (cajeros depositarios) se entreguen en las fechas acordadas Reuniones técnicas: Se sostuvieron reuniones de trabajo con el equipo de TI y el proveedor con el objetivo de revisar aspectos técnicos y funcionales clave para la implementación de los Cajeros Depositarios. Definición del flujo de transacciones: Se viene definiendo el flujo final de la transacción de depósito, incluyendo los escenarios de excepción, tanto para transacciones parciales como fallidos (por ejemplo, si el cliente no termina de ingresar todo el dinero). Transacciones que se habilitarán con Contactless (tarjeta o dispositivo sin contacto físico). Se encuentra en actualización el anexo N° 1 en el cual se incorporarán los requerimientos funcionales adicionales identificados. 13/08/2025: De acuerdo al Acta de Comité de Proyectos del 16/07 N°06-2025 se informa que: Se aprueba la solicitud de cambio con el presupuesto actualizado que asciende a S/866,956.74. 18/07/2025: Al 30.06.25, se viene realizando : -El seguimiento al proveedor para garantizar que la entrega de los equipos se realice oportunamente y con la calidad esperada. -Sesiones técnicas con el proveedor, avanzando las actividades de integración de la solución conjuntamente con TI; y en esos espacios se realiza el seguimiento de las fechas de la entrega de los bienes. Presentó CC por el presupuesto del proyecto. 07/07/2025: Actualmente se vienen desarrollando sesiones de trabajo conjuntas con la Gerencia de Tecnologías de Información y el proveedor Diebold, orientadas al diseño de la arquitectura de la solución y la gestión de los componentes de TI, en paralelo a la espera de la recepción física de los bienes. Asimismo sesiones con area usuario para definir el flujo funcional. 11/06/2025:Según la información enviada de Planeamiento en el mes de Mayo se precisa lo siguiente: Se están realizando sesiones de trabajo para el diseño de la arquitectura de solución y gestión de componente de TI en conjunto con el equipo de la Gerencia de Tecnologías de Información y el proveedor Diebold, mientras se espera la recepción física de los bienes. 03/06/2025: Según la información enviada de Planeamiento mediante correo respecto al proyecto al mes de abril se tiene que: Se realizó la firma correspondiente del contrato con el postor ganador Diebold Nixdorf Perú SRL., asimismo, se llevó a cabo la ceremonia del Kickoff con las áreas correspondientes. 07/05/2025: Según la información remitida por Planeamiento mediante correo: Para lograr el perfeccionamiento del contrato, el postor ganador Diebold logró subsanar las observaciones de la respectiva documentación en coordinación con el área de Logística e Innovación Digital, lo cual permitirá que la firma de contrato se pueda concretar dentro de los plazos previstos. 31/01/25: Para lograr el perfeccionamiento del contrato, el postor ganador Diebold logró subsanar las observaciones de la respectiva documentación en coordinación con el área de Logística e Innovación Digital, lo cual permitirá que la firma de contrato se pueda concretar dentro de los plazos previstos.En absolución de consultas y observaciones hasta este viernes 31ene25. 31/12/2024: Al 13.12.2024 se encuentra en proceso de reformulación de ETMs por resolución del Tribunal OSCE declaró nulo el proceso de selección (05.12.2024). El 27.12.2024 se convocó en el SEACE la LP-SM-4-2024-BN-1 23/05/24 Mediante acta de comité estratégico de proyectos con fecha 06.05.24 se aprobó el control de cambios del alcance del proyecto, los usuarios deben formalizar el nuevo cronograma del proyecto y remitirlo a planeamiento. 03/05/2024 Se ha devuelto Anexo 1 con observaciones 26/04/2024 Mediante correo de Pablo Arias se entrega el Anexo 1 del proyecto, el cuál se devuelve con observaciones notificadas dentro del documeneto al remitente en mención. A la espera de la devolución con observaciones levantadas, firmado y remitido por STD. 26/04/2024 A la espera de remitirse a TI el Anexo 1 y Anexo 2, asi mismo el registro de los requerimientos en OPP para su posterior categorización de cartera. 25/04/2024 Mediante Memo N° 63-2024-BN2810 en que se entrega la nueva lista de proyectos con componente TI se crea el proyecto en base de datos y se asigna el Lider usuario al proyecto, anteriormente no existia.
A9: 7 | B9: PRODNI-EO12-23-8 | C9: Proyecto Cuenta DNI – Nuevas Funcionalidades | D9: La cuenta DNI es una cuenta básica de ahorros de naturaleza digital y en moneda nacional | E9: Banca Digital | F9: Luis Palacios | G9: Por definir | H9: Juan Carlos Palomino | I9: 31894424 | J9: 500000 | K9: 400000 | L9: =Tabla3[[#This Row],[Valor Ganado (EV)]]/Tabla3[[#This Row],[Costo Actual (AC)]] -> 1.25 | M9: 45121 | N9: Acta Nº8-2023 | O9: Servicio a los Clientes | P9: De cara al ciudadano | Q9: 2023 | R9: 2025 | S9: 5 | T9: Si | U9: Sí | V9: Cuenta DNI (Cloud) | W9: Si | X9: Angela Risco | Y9: 45065 | Z9: 46112 | AA9: 0.76 | AB9: 0.71 | AC9: =Tabla3[[#This Row],[% Avance ejecutado]]-Tabla3[[#This Row],[% Avance Planificado]]/Tabla3[[#This Row],[% Avance Planificado]] -> -0.29 | AD9: 02. En Curso | AE9: 14/04/2026: En el mes de marzo, respecto a la ETAPA I: MVP2 (salida), se levantó la observación al Workbook por la CCE, lo que implicó un nuevo desarrollo por parte del proveedor Backbase y pruebas adicionales en ambiente de Calidad para la certificación y pase a producción de las funcionalidades: Transferencias interbancarias inmediatas de salida, Transferencias por contacto de salida y Transferencias mediante código QR de salida (canal móvil). 23/03/2026: En la ETAPA I (MVP2 salida) de Cuenta DNI, una observación de la CCE al Workbook requirió un nuevo desarrollo por Backbase y pruebas adicionales en Calidad, impactando las transferencias de salida (interbancarias inmediatas, por contacto y vía QR). 20/03/2026: Según el acta de reunión del comité de proyectos del mes de enero, el proyecto presentó un ligero retraso al cierre de diciembre 2025. Si bien el MVP2 completó el 100% de las pruebas funcionales en noviembre 2025, la Gerencia de TI solicitó a fines de diciembre realizar pruebas de vulnerabilidad a las APIs de Temenos. Se estima culminar el MPV2 para el mes de enero 2026. Asimismo, el Comité de Cuenta DNI debe evaluar y definir las acciones correspondientes respecto al proyecto. 25/02/2026: En la ETAPA I – MVP2 (salida) del proyecto Cuenta DNI se vienen ejecutando las validaciones de reportes contables para asegurar el correcto registro financiero de las nuevas funcionalidades. El proyecto se encuentra pendiente de aprobación de la Cámara de Compensación para autorizar el pase a producción de las funcionalidades de transferencias de salida, que incluyen transferencias interbancarias inmediatas, por contacto y mediante código QR. 21/01/2026: El MVP2 completó satisfactoriamente el 100 % de las pruebas funcionales en noviembre de 2025. Actualmente, el proyecto se encuentra en la fase de validación de reportes contables, con incidencias siendo analizadas y corregidas. Adicionalmente, la Gerencia de TI solicitó el 24/12/2025 la ejecución de pruebas de vulnerabilidad sobre las APIs de Temenos, las cuales se encuentran en proceso de ejecución. 31/10/2025: Según la información enviada de Planeamiento en el mes de Octubre se precisa lo siguiente: Se ha presentado una solicitud de cambio donde se estará llevando un mejor control del avance del proyecto, hasta el momento se han mantenido las fechas con los avances porcentuales correspondientes. 30/09/2025: Según la información enviada de Planeamiento en el mes de Septiembre se precisa lo siguiente: El proyecto presenta retrasos principalmente por dependencias externas con los proveedores Temenos, Backbase y Novatronic, cuyos servicios aún se encuentran en fase de pruebas en el ambiente de certificación. Se ha presentado una solicitud de cambio con el objetivo de establecer un mejor control del avance del proyecto. Hasta el momento, se vienen manteniendo las fechas establecidas, con los avances porcentuales correspondientes conforme al cronograma vigente. 16/09/2025: Según la información enviada de Planeamiento en el mes de Agosto se precisa lo siguiente: Debido a la suspensión temporal del servicio por parte de los proveedores, el proyecto se vio afectado en su cronograma de pruebas. Sin embargo, tras regularizar los pagos correspondientes, el servicio fue restablecido y se han retomado las pruebas de manera satisfactoria, dando continuidad a la ejecución del proyecto. 21/08/2025: De acuerdo al Acta de Comité de Proyectos del 14/08 N°07-2025 se informa que: Se solicita a la Gerencia de Banca Digital realizar un informe situacional del proyecto y formalizar su solicitud de cambio para el próximo Comité Ejecutivo de Proyectos. Además, se solicita una reunión entre la Gerencia de Banca Digital, Gerencia Legal y la Gerencia de Administración y Logística para revisar el contrato con los proveedores del proyecto. Preliminar a ello, la Gerencia de Banca Digital debe confirmar si tuvo algún tipo de comunicación con los proveedores en relación con el contrato. 18/08/25: Según la información enviada de Planeamiento en el mes de Julio se precisa lo siguiente: El proyecto avanza conforme al road map (Hoja de Ruta) establecido; sin embargo, se registran demoras en las pruebas integrales debido a la alta complejidad de la integración entre BackBase, Temenos, Novatronic y CCE, así como a inconvenientes en los pagos a proveedores, lo que ha afectado la continuidad de las actividades. Se avanza en la configuración del servidor que gestionará las tarifas aplicables a las transferencias inmediatas, elemento clave para garantizar el correcto cálculo y aplicación de comisiones en la operación del servicio. 13/08/2025: De acuerdo al Acta de Comité de Proyectos del 16/07 N°06-2025 se informa que: la Gerencia de Banca Digital indicó que el proyecto terminará a fines de octubre 2025. En virtud de ello, se solicita el apoyo de todos los participantes para culminar en el periodo mencionado. 18/07/2025: Se están realizando pruebas en el ambiente de calidad de las funcionalidades de transferencias interbancarias inmediatas y pagos con QR, con los tres proveedores involucrados: Backbase, Temenos y Novatronic. Durante estas pruebas se han identificado incidencias relacionadas con la conexión a la Cámara de Compensaciones Electrónicas (CCE), debido a que se trata de un servicio compartido entre las áreas de TI. • El pase a producción está programado para agosto del MPV2 y para noviembre del MPV3 . • Actualmente se vienen desarrollando reuniones de seguimiento con el objetivo de supervisar el avance y la resolución de incidencias durante las pruebas. 11/06/2025:Según la información enviada de Planeamiento en el mes de Mayo se precisa lo siguiente: Durante la ejecución de las pruebas integrales en el entorno de desarrollo, en las que participan los tres proveedores (Backbase, Temenos y Novatronic), se han identificado incidencias relacionadas con la conexión a la Cámara de Compensaciones y con los tiempos de respuesta en las operaciones correspondientes al proceso de interoperabilidad (transferencias interbancarias inmediatas y pagos con QR). -Estas situaciones vienen siendo atendidas de manera conjunta por Novatronic, Temenos y el Banco de la Nación. 03/06/2025: Según la información enviada de Planeamiento mediante correo respecto al proyecto en el mes de abril se tiene que: Durante las pruebas integrales (participación de los 3 proveedores) se presentó incidencias con el tarifario dinámico que interactúa con todo el proceso de interoperabilidad (transferencias interbancarias inmediatas, pago con QR) la que está siendo atendidas por Novatronic. Asimismo, el proveedor Tenemos, presentó incidente en la data que se trasmite al core T24. Se realizan reuniones de seguimiento 2 veces al día para el seguimiento de las pruebas y corrección de los incidentes Se estima culminar las pruebas en desarrollo la primera semana de mayo iniciar pruebas en el ambiente de Calidad. 07/05/2025: Según la información enviada por Planeamiento mediante correo: Se continúan las pruebas en desarrollo de las funcionalidades de transferencias inmediatas, por contacto y QR con el proveedor BACKBASE, TEMENOS y NOVATRONIC. Se mantienen las pruebas en desarrollo de las funcionalidades de retiro y deposito en agente BN y para retiro y depósito en ventanilla con el proveedor TEMENOS y el BN. 31/12/2024: Las áreas usuarias validaron las funcionalidades de retiro y depósito en Ventanilla y se procedió con la generación del Anexo 2 para solicitar la inscripción en el Clear Quest. Se continúan coordinando con el proveedor Temenos para correcciones. Siguen en construcción la funcionalidad de transferencias Q 23/05/24 Mediante comité estratégico de proyectos con fecha 06.05.24 se aprobó el control de cambios del proyecto.Esto implica nuevas actividades y actualizacion en el cronograma. TI solicitará al usuario remtiir anexo 1 actualizado. 08/04/24 Se cambió la fecha de Fin de proyecto a 2025 20/03/24 Usuario remitió modelo de negocio y se registró en la demanda estrategica de TI, sin embargo se encuentra pendiente que el usuario remita modelo de negocio actualizado. Está retrasado porque el proveedor no contempló dentro del cronograma actividades funcionales que son necesarias para el proytecto. Presentarán un control de cambios a nivel de alcance, tiempo y presupuesto.
A10: 8 | B10: PROGRO-EO08-23-12 | C10: Servicio de Implementación y Licenciamiento de un Software para la Gestión del Riesgo Operacional, Seguridad de la Información y Continuidad del Negocio para el BN | D10: Fortalecer la Gestión de Riesgo Operacional, Seguridad de la Información y Continuidad del Negocio del Banco de la Nación | E10: Riesgos | F10: Victoria Galvez | G10: Diana Mogollon | H10: Rina Roca | I10: 1884223 | M10: 45121 | N10: Acta Nº8-2023 | O10: Tecnológica | P10: Gestión Interna | Q10: 2023 | R10: 2025 | S10: 3 | T10: Si | U10: Sí | V10: Riesgo Operacional | W10: Si | X10: Jorge Mora | Y10: 45110 | Z10: 46052 | AA10: 0.97 | AB10: 0.97 | AC10: =Tabla3[[#This Row],[% Avance ejecutado]]-Tabla3[[#This Row],[% Avance Planificado]]/Tabla3[[#This Row],[% Avance Planificado]] -> -0.03 | AD10: 02. En Curso | AE10: 14/04/2026: En el mes de marzo, al cierre se realizó el pase al ambiente de Certificación tras pruebas de usuario e integración, identificándose cinco (5) casos de prueba con observaciones y dos (2) vulnerabilidades de severidad media, a ser subsanadas por el proveedor en la actualización del 30.04.2026; asimismo, se presentaron inconvenientes en la gestión de accesos al servidor IVANTI para Achiwan (Telefónica Tech) y Clarity (prov. Ivanti), generando demoras en el inicio de pruebas de integración en Desarrollo, situación que a la fecha se encuentra superada para continuar con el pase a calidad. 23/03/2026: En febrero se actualizó la herramienta para corregir observaciones y vulnerabilidades detectadas en Calidad; un nuevo escaneo identificó dos vulnerabilidades medias, ya comunicadas al proveedor para su remediación. Además, se iniciaron pruebas de usuario con TI y las gestiones para la solicitud de cambios del proyecto. 20/03/2026: Según el acta de reunión del comité de proyectos del mes de enero, el proyecto marchó de acuerdo a lo planificado al cierre de diciembre 2025. En enero 2026 se efectuó el pase al ambiente de Certificación. Sin embargo, el proyecto ha presentado demoras en la actividad "Despliegue en calidad" debido a inconvenientes en el despliegue de la aplicación Global Suite y a problemas en la carga de datos en el servidor, lo cual puede impactar en la culminación del proyecto en enero 2026. 25/02/2026: Durante el proceso de Certificación del BN se identificaron vulnerabilidades, por lo que TI–Seguridad solicitó al proveedor su subsanación como condición para el pase a producción. La herramienta fue actualizada, pero no se corrigieron todas las vulnerabilidades. Posteriormente, en las pruebas de calidad y usuario, se detectaron nuevos errores funcionales y la reaparición de errores ya subsanados, los cuales fueron remitidos al proveedor y continúan pendientes de corrección; en consecuencia, se formulará una solicitud de cambio. 21/01/2026: Al 12.12.2025 se concluyeron los entregables hasta el E10 y se realizó el pase a Certificación. El E11 (Proceso de Certificación del BN) presenta demoras en “Despliegue en Calidad” por inconvenientes en GlobalSuite y en la carga de data del ETL, los cuales vienen siendo subsanados. Es necesario culminar el E11 para iniciar las pruebas de calidad y usuario, para lo cual se vienen coordinando reuniones adicionales. En el levantamiento de vulnerabilidades se identificaron 6 vulnerabilidades medias: 5 falsos positivos y 1 vulnerabilidad pendiente (CSP: Directiva Wildcard), con fecha comprometida 11.01.2026. 30/11/2025: Se logró el cierre del entregable 6 "Parametrizacion del modulo Administracion" y del entregable 8 "Parametrizacion del módulo de seguridad de la informacion". Con respecto al entregable 7 "Parametrizacion del modulo de Riesgo Operacional" en la actividad de configuracion de reportes, hubo observaciones funcionales en la reporteria que esta generando demoras en la implementacion del entregable, por lo que el proveedor se encuentra subsanando las observaciones para la primera semana de diciembre se estima su conclusión. En el entregable 10 "Pruebas en ambiente de desarrollo", en la actividad analisis de vulnerabilidades, el area de la Seguridad de la informacion realizo escaneos y encontro vulnerabilidades que estan pendientes de subsanar por parte del proveedor." 31/10/2025: Según la información enviada de Planeamiento en el mes de Octubre se precisa lo siguiente: "Al 31.10.2025, se efectuaron las siguientes actividades del entregable ""Instalación, configuración e integracion de la solución"" en el amibiente de desarrollo: 1. Iimplementacion de la reporteria BI.(10/02/2025). Concluido al 100% 2. Integración IBM -ISIM con la herrramienta GlobalSuite( 10/02/2025). Concluido al 100% Asimismo, se elaboró los documentos para la solicitud de cambio con la actualización del cronograma coordinado con la Gerencia de TI." 30/09/2025: Según la información enviada de Planeamiento en el mes de Septiembre se precisa lo siguiente: En cuanto a la Implementación de la Reporteria BI (dentro del Entregable 5), se solucionó la habilitación de servidor y actualmente el proveedor está configurando el servidor con los componentes necesarios para la reportería. Con respecto a la Integración ISIM ( dentro del Entregable 5), el proveedor Telefonica Tech, con apoyo de un proveedor local especializado, ha desarrollado el conector para la integración ISIM y actualmente se encuentra en proceso de configuración para integrar los perfiles requeridos para la herramienta GlosbSuite. 16/09/2025:Según la información enviada de Planeamiento en el mes de Agosto se precisa lo siguiente: A la fecha; la solicitud de ampliación de los plazos solicitada por el proveedor fue evaluada por el área de Logística y Legal, previos informes de la Subgerencia de Riesgos de Operación y Tecnología, concluyendo que no procede la ampliación por lo que se aplicaría las penalidades previa conformidad del área usuaria. Asimismo, continúan las coordinaciones con la Gerencia de TI para la habilitación de (01) servidor y (01) Instancia de base datos al proveedor para la generación de reportería BI. Asimismo, se viene elaborando cronograma considerando nuevos plazos con fecha fin estimada de proyecto (dic 2025). Se procederá a la presentación de la solicitud de cambios en el próximo comité de proyectos. 21/08/2025: De acuerdo al Acta de Comité de Proyectos del 14/08 N°07-2025 se informa que: Se solicita a la Gerencia de Riesgos realizar un informe situacional del proyecto y formalizar su solicitud de cambio para el próximo Comité Ejecutivo de Proyectos. 13/08/2025: De acuerdo al Acta de Comité de Proyectos del 16/07 N°06-2025 se informa que: El Jefe de Sección Políticas de Seguridad de Información de la Gerencia de Riesgos expuso las dificultades técnicas del proyecto. Ante ello, se solicita a la Gerencia de TI coordine y brinde el apoyo tecnológico necesario para continuar con las actividades del proyecto. Asimismo, la Gerencia de Riesgos, líder del proyecto, deberá revisar si el contrato con el proveedor define penalidades por incumplimiento y deberá remitir el calendario actualizado luego de su gestión de ampliación con el proveedor. 18/08/25: Según la información enviada de Planeamiento en el mes de Julio se precisa lo siguiente: Se continúa con el proceso de implementación de las funcionalidades de los módulos de Administración, Riesgo Operacional, Seguridad de la Información y Continuidad de Negocio. Sin embargo, no se concluyó con la fecha fin del proyecto planificada debido principalmente a la demora en la implementación de la reportería BI - (40) (Bussines Inteligent) por parte del proveedor y de la alta dependencia del fabricante del software (GlobalSuite). En ese sentido, el proveedor remitió carta (31.07.25) comunicando la necesidad de solicitar la ampliación de los plazos establecidos en el contrato. A la fecha, el área líder el proyecto viene elaborando la solicitud al proveedor del nuevo cronograma y a su vez coordinando la solicitud de la habilitación de (02) servidores (base de datos y ETL-Extracción de Información, transformación y carga de datos a la Gerencia de TI . 18/07/2025: Se continúa avanzando el proceso de implementación de las funcionalidades de los módulos de Administración, Riesgo Operacional, Seguridad de la Información y Continuidad de Negocio; que han presentado demoras por parte del proveedor por la alta dependencia del fabricante del software. Se han finalizado las integraciones a Oracle, Ivanti, Directorio Activo y alertas a los correos. Telefónica Techh se encuentra desarrollando el conector ISIM-Globalsuite e implementación de la reportería por módulos. Esta pendiente remitir la carta al proveedor por los retrasos de los compromisos del proyecto. 11/06/2025:Según la información enviada de Planeamiento en el mes de Mayo se precisa lo siguiente: Hay retrasos en las tareas de reportería, conector ISIM, pruebas, etc., Estos se deben a la alta dependencia de Telefónica con su partner Global Suite. En abril se reporto avance de 43%, proyecto tiene fecha de fin julio 2025. 03/06/2025: Según la información enviada de Planeamiento mediante correo respecto al proyecto en el mes de abril se tiene que: Los retrasos en las tareas como reportería, conectores ISIM, etc., se deben a la dependencia de Telefónica con su partner GlobalSuite. Adicionalmente, la limitada flexibilidad del proveedor para ofrecer alternativas a los impases está generando demoras en los ajustes y aprobaciones del área de riesgo 07/05/2025: Según la información remitida por Planeamiento mediante correo: Se han completado 4 de los 15 entregables. El quinto está retrasado por incumplimientos de Global Suite. Por lo que se espera sean superadas en abril. 31/12/2024: Esta en ejecución las tareas: Instalación, Parametrización, Conversión y Migración que tienen retrasos de hasta 7 meses ,debido a las integraciones con las Aplicaciones IVANTI y Oracle y las pruebas de los módulos nuevos con los usuarios. 22/05/24 Usuario presentará un control de cambios; confirman que culminan este año 2024. Contrato firmado el 15/05/24, revisar Memo 086-2024/2182 donde solicitan apoyo de TI.AO24 03/05/2024 En proceso logístico para el otorgamiento de Buena pro 08/04/24 Se ha cambiado la fecha de Fin de proyecto de 2025 a 2024. 20/03/24 Está retrasado en la suscripcion del contrato. Se agendará una reunión para revisar las siguientes actividades que involucra a TI según cronograma. Pendiente que el usuario remita modelo de negocio para registrar el Proyecto en la demanda estrategica priorizada. Pendiente envío Modelo de Negocio
A11: 9 | B11: PROPLAFT-EO08-23-13 | C11: Implementación de la Solución tecnológica para la prevención de fraudes, lavado de activos y del financiamiento del terrorismo (LA/FT) y aplicación de scoring de riesgos de LA/FT | D11: El proyecto que inició el 19.03.2021, consiste en implementar una solución tecnológica conformada por hardware (opcional), Software, Capacitación o entrenamiento y Servicios orientada a monitorear transacciones sospechosas a fin de prevenir y/o detectar oportunamente operaciones fraudulentas y/o de presunto lavado de activos y financiamiento del terrorismo en el Banco de la Nación (en adelante BN) a nivel Nacional. | E11: Riesgos | F11: Victoria Galvez | G11: Luis Garcia; Liliana Casafranca | H11: Maria Isabel Elguera | I11: 11876435 | M11: 45121 | N11: Acta Nº8-2023 | O11: Tecnológica | P11: De cara al ciudadano | Q11: 2021 | R11: 2025 | S11: 3 | T11: Si | U11: Sí | V11: Sentinel | W11: Si | X11: Jorge Ruiz | Y11: 44274 | Z11: 46160 | AC11: =Tabla3[[#This Row],[% Avance ejecutado]]-Tabla3[[#This Row],[% Avance Planificado]]/Tabla3[[#This Row],[% Avance Planificado]] -> #DIV/0! | AD11: 02. En Curso | AE11: 14/04/2026: En el mes de marzo, respecto al Entregable 9 se realizó la integración con los canales ATM, AGENTE y VISA; y respecto al Entregable 12 se inició la actualización del perfil transaccional, la cual culminará a principios de junio de 2026. 23/03/2026: Para el cierre de febrero, se viene coordinando con el proveedor la entrega del cronograma detallado de actividades, en el cual se evidencian los porcentajes de avance. Se estima contar con dicha información en marzo. 20/03/2026: Según el acta de reunión del comité de proyectos del mes de enero, el proyecto presentó un ligero retraso al cierre de diciembre 2025, no logrando culminar la implementación de los 03 procesos planificados para el 2025, debido a que no se tenía la información homologada. La Gerencia de Operaciones señaló que espera culminar con las pruebas pendientes a fines de enero 2026. 25/02/2026: En enero no se registraron nuevos entregables en producción; no obstante, se avanzó en actividades de los Entregables 7 y 9. Asimismo, se viene coordinando con el Consorcio la actualización de fechas de compromiso para las próximas salidas a producción de los Entregables 7, 9 y 12, estimándose contar con un cronograma consensuado la próxima semana 21/01/2026: Finalización de pruebas de Modelos basados en Reglas; redacción y conformidad de actas de pruebas en Desarrollo y Certificación; gestiones para la reducción de la prestación del Canal Banca Celular; aceptación y cierre del Entregable N°10 (pase a producción 10.12.2025); validación post-producción de Reglas en App Móvil y HomeBanking.La culminación del Entregable N°11 depende de la culminación del Entregable N°9, dado que el informe de avance comprende los entregables 9 y 10. 30/11/2025: En noviembre se efectuó el pase a producción correspondiente a la parte funcional de la herramienta (fase 1) correspondiente al Proyecto Sentinel. Durante diciembre se completará el pase a producción de la fase 2, lo que permitiría considerar el entregable 10 como finalizado al 100%. No obstante, al cierre de noviembre ningún entregable posterior al número 6 alcanza el 100% de avance. A la fecha el proyecto es medido a nivel entregables debido a que no han compartido el cronograma detallado del proyecto. 31/10/2025: Según la información enviada de Planeamiento en el mes de Octubre se precisa lo siguiente: Su nivel de avance es a nivel entregables ya que no se cuenta con un cronograma detallado. Asimismo, está presentado una solicitud de cambio donde el proyecto culminaría en Mayo 2026. 30/09/2025: Según la información enviada de Planeamiento en el mes de Septiembre se precisa lo siguiente: La gerencia de riesgos en coordinación con la gerencia de TI ha elaborado un nuevo cronograma a fin de que el proveedor lo revise y de la conformidad. Dicho cronograma acompañado de un informe por la gerencia de riesgos fue presentado al Directorio. Ante ello, la sesión de Directorio ha determinado que se brindará lo necesario para acotar los plazos. 16/09/2025:Según la información enviada de Planeamiento en el mes de Agosto se precisa lo siguiente: La gerencia de Riesgos no ha reportado % de avance en el mes de agosto 2025. 21/08/2025: De acuerdo al Acta de Comité de Proyectos del 14/08 N°07-2025 se informa que: Se solicita a la Gerencia de Riesgos realizar un informe situacional del proyecto y formalizar su solicitud de cambio para el próximo Comité Ejecutivo de Proyectos. 18/08/25: Según la información enviada de Planeamiento en el mes de Julio se precisa lo siguiente: - Hay Entregables vencidos (6 de 12) - Cronograma desactualizado (fecha fin: Junio 2025) - La gerencia líder del proyecto no reporta información del estado del proyecto. 13/08/2025: De acuerdo al Acta de Comité de Proyectos del 16/07 N°06-2025 se informa que: No presentaron reporte al cierre de junio a la Sub Gerencia de Planeamiento. Sin embargo, se está efectuando reuniones semanales entre las gerencias participantes y la Gerencia General para monitorear у tomar decisiones en conjunto respecto a actividades propias del BN, así como coordinar actividades con el proveedor. 18/07/2025: Se tuvo una reunión el 16.06.2025 entre las gerencias de TI, gerencia de Riesgos, OPLAFT y Planeamiento. Se expuso que el cronograma que se envió al proveedor no ha sido aceptado debido a que no comtempla las fechas solicitadas para finalizar el 2025. Por otro lado, las áreas usuarias contemplan que hay data que trabajar para poder darsela al proveedor y cumplir con las actividades planificadas. Por otro lado, va a ver una reunión con legal para ver temas contractuales con el proveedor. 11/06/2025:Según la información enviada de Planeamiento en el mes de Mayo se precisa lo siguiente: Entregable 7 Fase 2 Ambiente de Desarrollo continúan las pruebas de perfiles ,funcionales y la validación de Calidad de datos de los archivos de 5 días, en paralelo se están generando desde 2/5 los archivos de 6 meses con los programas extractores v2 . Entregable 9 se culmino la integración de datos desde los canales en el ambiente Desarrollo. Entregable 10 se culmino las pruebas en el ambiente de Certificación esta en proceso la firma de los IRPF y RC . 03/06/2025: Según la información enviada de Planeamiento mediante correo respecto al proyecto en el mes de abril se tiene que: Se encuentra en actualización el Cronograma entre el BN y SS el cual generara la versión 3. Se desplego la versión 7.12.1 de Sentinel Core y Predictions en el ambiente de desarrollo. 07/05/2025: Según la información remitida por Planeamiento mediante correo: Se esta desplegando la nueva versión de Sentinel Core y Predictions que resuelve issues identificadas durante las pruebas hasta dic 2024. Entregable 7 La revisión de Calidad de datos no se esta cumpliendo en fecha debido a la que la información aun sigue siendo corregida por parte de TI-BN , existe una alta dependencia de un solo especialista para el análisis y construcción de los programas extractores . Entregable 9 Hay retraso en el inicio de las pruebas funcionales en el ambiente de desarrollo debido a las actividades previas por parte de TI-BN y Smartsoft. Entregable 10 Aún están pendientes de firma las RC , ya que dependen de los IRPF, tanto de Producto como Funcional, los cuales no han sido remitidos con las firmas correspondientes por parte de Smartsoft. Una vez que Smartsoft entregue los IRPF debidamente visados, los usuarios y el equipo de TI - BN procederán con el visado final para su cierre. 31/12/2024: A nivel entregables se encuentran en ejecución 4 entregables. OPLAFT El entregable 7 se encuentra a un 86 %. Se culmino la certificación de la Fase 1 (Productos y Perfiles). Fraudes El entregable 9 se encuentra a un 70 %. Se definió el tema de las pruebas RT y NRT . El entregable 10 se encuentra a un 65 %. El entregable 12 se encuentra a un 92 % Se culmino la certificación. 23/05/2024 Mediante Comité Estratégico de proyectos de fecha 06.05.24 se informa la aprobación de control de cambios del proyecto 08/04/24 Se ha cambiado la fecha de inicio de proyecto de 2023 a 2021 20/03/24 TI compartirá con Planeamiento el nuevo plan actualizado para que se gestione el control de cambios con el Líder del Proyecto.
A12: 10 | B12: PROASL-EO10-23-18 | C12: Adquisición de Switches Lan para las sedes Administrativas y dependencias del BN | D12: Renovar los equipos de comunicaciones que brindan el acceso a la red del banco a los usuarios administrativos y de las dependencias como Agencias, Lobbys y Oficinas especiales, usando protocolos de seguridad y acceso actualizados y estándares en la industria de Tl. | E12: Tecnologías de Información | F12: Alejandro Sifuentes | G12: - | H12: No definido | I12: 7584500 | J12: =Tabla3[[#This Row],[Presupuesto asignado]]/2 -> 3792250 | K12: =Tabla3[[#This Row],[Valor Ganado (EV)]] -> 3792250 | L12: =Tabla3[[#This Row],[Valor Ganado (EV)]]/Tabla3[[#This Row],[Costo Actual (AC)]] -> 1 | M12: 45121 | N12: Acta Nº8-2023 | O12: Tecnológica | P12: De cara al ciudadano | Q12: 2023 | R12: 2025 | S12: 0 | T12: Si | U12: Sí | V12: Switches LAN | W12: Si | X12: Erick Romero | Y12: 44928 | Z12: 45774 | AA12: 1 | AB12: 1 | AC12: =Tabla3[[#This Row],[% Avance ejecutado]]-Tabla3[[#This Row],[% Avance Planificado]]/Tabla3[[#This Row],[% Avance Planificado]] -> 0 | AD12: 03. Implementado | AE12: IMPLEMENTADO 11/06/2025:Según la información enviada de Planeamiento en el mes de Mayo se precisa lo siguiente: El Equipo Técnico del proyecto informó que, se culminó con la implementación al 100%. Asimismo, se presentó el avance de las siguientes actividades: Implementación: Ejecución: 100% (finalizado) Monitoreo y Control: 100% (finalizado) Cierre 100% (finalizado) 03/06/2025: Según la información enviada de Planeamiento mediante correo respecto al proyecto en el mes de abril se tiene que: El proyecto ha sido culminado. Fin del Proyecto. 21/05/2025: Según el Acta de Reunión N°04-2025 del Comité de Proyectos, se enviará a Planeamiento el Acta de Cierre del Proyecto y el fomato de lecciones aprendidas en las próximas semanas. 07/05/2025: Según la información remitida por Planeamiento mediante correo: A nivel tareas, actualmente se encuentra en la Etapa de Implementación del Proyecto. El Equipo Técnico del proyecto informó que, solo faltan instalar 45 equipos de 547 nuevos equipos en la Red de Agencias. Además, se revisaron posibles riesgos y desafíos que podrían impactar el cronograma, con el objetivo de tomar medidas preventivas y correctivas. Finalmente, se comunicó que las actividades del proyecto se vienen realizando de acuerdo a lo planificado. Asimismo, se presentó el avance de las siguientes actividades: • Implementación: Ejecución: 96% (en proceso) Monitoreo y Control: 97% (casi finalizado) 31/12/2024: *Se instalaron 280 switches para las sedes administrativas así como la implementación de los servidores plataforma de gestión, la solución NAC y Control de accesos. Dado esto, se viene realizando la entrega de la conformidad del servicio para el pago correspondiente por esta primera etapa. * Los usuarios de Canales Virtuales y Red de Agencias solicitaron no realizar trabajos durante esta semana por lo que se suspenden las actividades hasta el mes de enero. 23/05/24 Validar si se firmó el contrato. A espera que el proveedor entregue el plan de trabajo. 25/04/2024 Mediante Memo N° 63-2024-BN2810 en que se entrega la nueva lista de proyectos con componente TI se genera cambio en el lider del proyecto de José Macedo a Alejandro Sifuentes 25/04/2024 Mediante Memo N°60-2024-BN2810 se informa que se requiere el informe de las razones del retraso del proyecto asi como sus acciones correctivas para la presentación al comité del 26.04 20/03/24 Esta en proceso logistico (analisis de oferta y la buena pro se dará en marzo). Presentarán un nuevo cronograma con control de cambios.
